<!-- <?xml version="1.0" ?> -->
<!-- =================================================================================== -->
<!-- |    This document was autogenerated by xacro from world.xacro                    | -->
<!-- |    EDITING THIS FILE BY HAND IS NOT RECOMMENDED                                 | -->
<!-- =================================================================================== -->
<robot name="allegro_hand_curved"> 
  <link name="world"/>
  <!-- Rviz colors -->
  <material name="black">
    <color rgba="0.1 0.1 0.1 1.0"/>
  </material>
  <material name="blue">
    <color rgba="0.0 0.0 0.8 1.0"/>
  </material>
  <material name="green">
    <color rgba="0.0 0.8 0.0 1.0"/>
  </material>
  <material name="grey">
    <color rgba="0.2 0.2 0.2 1.0"/>
  </material>
  <material name="orange">
    <color rgba="1.0 0.4235294117647059 0.0392156862745098 1.0"/>
  </material>
  <material name="brown">
    <color rgba="0.8705882352941177 0.8117647058823529 0.7647058823529411 1.0"/>
  </material>
  <material name="red">
    <color rgba="0.8 0.0 0.0 1.0"/>
  </material>
  <material name="white">
    <color rgba="1.0 1.0 1.0 1.0"/>
  </material>
  <!-- <joint name="allegro_hand_base_joint" type="fixed">
    <origin rpy="0.0 1.5708 0" xyz="0.0 0 0.132"/>
    <parent link="world"/>
    <child link="allegro_hand_base_link"/>
  </joint> -->
  <!-- <link name="allegro_hand_base_link"> -->
  <link name="allegro_hand_base_link">
    <visual>
      <geometry>
        <mesh filename="xela/allegro/base_ns.stl"/>
      </geometry>
      <origin rpy="0 0 0" xyz="0 0 0 "/>
      <material name="black">
        <color rgba="0.0 1.0 1.0 1"/>
      </material>
    </visual>
    <collision>
      <!-- <origin rpy="0 0 0" xyz="-0.009300 0 -0.0475"/> -->
      <geometry>
        <mesh filename="xela/allegro/base_ns.stl"/>
        <!-- <box size="0.0408 0.1130 0.095"/> -->
      </geometry>
    </collision>
    <inertial>
      <mass value="0.4154"/>
      <origin rpy="0 0 0" xyz="0 0 0"/>
      <inertia ixx="1.87e-03" ixy="0.0" ixz="8.31e-06" iyy="1.13e-03" iyz="0.0" izz="1.11e-03"/>
    </inertial>
  </link>
  <link name="allegro_hand_hitosashi_finger_finger_link_0">
    <visual>
      <geometry>
        <mesh filename="xela/allegro/link_0.0_ext.STL"/>
      </geometry>
      <material name="grey"/>
    </visual>
    <collision>
      <geometry>
        <box size="0.0196 0.0275 0.0164"/>
      </geometry>
      <origin rpy="0 0 0" xyz="0 0 0.011200000000000002"/>
    </collision>
    <inertial>
      <mass value="0.0127"/>
      <origin rpy="0 0 0" xyz="0 0 0"/>
      <inertia ixx="1.138e-06" ixy="1.27e-10" ixz="4.83e-09" iyy="6.683e-07" iyz="0.0" izz="0.0010001160000000001"/>
    </inertial>
  </link>
  <joint name="allegro_hand_hitosashi_finger_finger_joint_0" type="revolute">
    <axis xyz="0 0 1"/>
    <limit effort="30" lower="-0.47" upper="0.47" velocity="0.5"/>
    <parent link="allegro_hand_base_link"/>
    <child link="allegro_hand_hitosashi_finger_finger_link_0"/>
    <origin rpy="-0.08726646259971647 0 0" xyz="0 0.0435 -0.001542"/>
  </joint>
  <link name="allegro_hand_hitosashi_finger_finger_link_1">
    <visual>
      <geometry>
        <mesh filename="xela/allegro/link_1.0.stl"/>
      </geometry>
      <material name="black"/>
    </visual>
    <collision>
      <geometry>
        <mesh filename="xela/allegro/link_1.0.stl"/>
        <!-- <box size="0.0196 0.0275 0.0164"/> -->
      </geometry>
      <!-- <origin rpy="0 0 0" xyz="0 0 0.0082"/> -->
    </collision>
    <inertial>
      <mass value="0.809"/>
      <origin rpy="0 0 0" xyz="0 0 0"/>
      <inertia ixx="7.95654166667e-05" ixy="1.7199e-05" ixz="8.75875e-06" iyy="0.0010247088833333" iyz="2.413125e-05" izz="7.95654166667e-05"/>
    </inertial>
  </link>
  <!--covers are always with sensors-->
  <link name="allegro_hand_hitosashi_finger_finger_link_1_cover">
    <visual>
      <geometry>
        <mesh filename="xela/allegro/link_1_cover.stl"/>
      </geometry>
      <material name="black"/>
    </visual>
    <!-- <collision>
      <geometry>
        <mesh filename="xela/allegro/link_1_cover.stl"/>
      </geometry>
    </collision> -->
    <!--As link is fixed, inertias will be inside the main link-->
  </link>
  <joint name="allegro_hand_hitosashi_finger_finger_link_1_cover_joint" type="fixed">
    <origin rpy="0.0 0.0 0.0" xyz="0.0 0.0 0.0"/>
    <parent link="allegro_hand_hitosashi_finger_finger_link_1"/>
    <child link="allegro_hand_hitosashi_finger_finger_link_1_cover"/>
  </joint>
  <joint name="allegro_hand_hitosashi_finger_finger_joint_1" type="revolute">
    <limit effort="30" lower="-0.19599999999999998" upper="1.6099999999999999" velocity="0.5"/>
    <axis xyz="0 1 0"/>
    <parent link="allegro_hand_hitosashi_finger_finger_link_0"/>
    <child link="allegro_hand_hitosashi_finger_finger_link_1"/>
    <origin xyz="0 0 0.0204"/>
    <!-- New height on fingers -->
  </joint>
  <link name="allegro_hand_hitosashi_finger_finger_link_2">
    <visual>
      <geometry>
        <mesh filename="xela/allegro/link_2.0.stl"/>
      </geometry>
      <material name="black"/>
    </visual>
    <collision>
      <geometry>
        <box size="0.0196 0.0275 0.054"/>
      </geometry>
      <origin rpy="0 0 0" xyz="0 0 0.027"/>
    </collision>
    <!--covers are always with sensors-->
    <inertial>
      <mass value="0.0447"/>
      <origin rpy="0 0 0" xyz="0 0 0"/>
      <inertia ixx="2.63979183333e-05" ixy="6.67968e-06" ixz="4.783625e-06" iyy="0.0010134948516667" iyz="9.372e-06" izz="2.63979183333e-05"/>
    </inertial>
  </link>
  <link name="allegro_hand_hitosashi_finger_finger_link_2_cover">
    <visual>
      <geometry>
        <mesh filename="xela/allegro/link_2_cover.stl"/>
      </geometry>
      <material name="black"/>
    </visual>
    <!-- <collision>
      <geometry>
        <mesh filename="xela/allegro/link_2_cover.stl"/>
      </geometry>
    </collision> -->
  </link>
  <joint name="allegro_hand_hitosashi_finger_finger_link_2_cover_joint" type="fixed">
    <origin rpy="0.0 0.0 0.0" xyz="0.0 0.0 0.0"/>
    <parent link="allegro_hand_hitosashi_finger_finger_link_2"/>
    <child link="allegro_hand_hitosashi_finger_finger_link_2_cover"/>
  </joint>
  <joint name="allegro_hand_hitosashi_finger_finger_joint_2" type="revolute">
    <axis xyz="0 1 0"/>
    <limit effort="30" lower="-0.17400000000000002" upper="1.7089999999999999" velocity="0.5"/>
    <parent link="allegro_hand_hitosashi_finger_finger_link_1"/>
    <child link="allegro_hand_hitosashi_finger_finger_link_2"/>
    <origin xyz="0 0 0.054"/>
  </joint>
  <link name="allegro_hand_hitosashi_finger_finger_link_3">
    <visual>
      <geometry>
        <mesh filename="xela/allegro/link_3.0.STL"/>
      </geometry>
      <material name="black"/>
    </visual>
    <collision>
      <geometry>
        <box size="0.0196 0.0275 0.026399999999999996"/>
      </geometry>
      <origin rpy="0 0 0" xyz="0 0 0.013199999999999998"/>
    </collision>
    <inertial>
      <mass value="0.0404"/>
      <origin rpy="0 0 0" xyz="0 0 0"/>
      <inertia ixx="4.701248e-06" ixy="1.255968e-06" ixz="1.2936e-06" iyy="0.001003649312" iyz="1.7622e-06" izz="4.701248e-06"/>
    </inertial>
  </link>
  <joint name="allegro_hand_hitosashi_finger_finger_joint_3" type="revolute">
    <axis xyz="0 1 0"/>
    <limit effort="30" lower="-0.227" upper="1.6179999999999999" velocity="0.5"/>
    <parent link="allegro_hand_hitosashi_finger_finger_link_2"/>
    <child link="allegro_hand_hitosashi_finger_finger_link_3"/>
    <origin xyz="0 0.0 0.0384"/>
  </joint>
  <joint name="allegro_hand_hitosashi_finger_finger_0_aftc_fixed" type="fixed">
    <origin rpy="1.5707963267948966 0.0 1.5707963267948966" xyz="-0.013 0.0 0.016"/>
    <parent link="allegro_hand_hitosashi_finger_finger_link_3"/>
    <child link="allegro_hand_hitosashi_finger_finger_0_aftc_base_link"/>
  </joint>
  <link name="allegro_hand_hitosashi_finger_finger_0_aftc_base_link">
    <collision>
      <origin rpy="0 0 0" xyz="0 0 0"/>
      <geometry>
        <mesh filename="xela/ft_c.stl"/>
      </geometry>
    </collision>
    <visual>
      <origin rpy="0 0 0" xyz="0 0 0"/>
      <geometry>
        <mesh filename="xela/ft_c.stl"/>
      </geometry>
      <material name="black"/>
    </visual>
  </link>
  <link name="allegro_hand_jaka_finger_finger_link_4">
    <visual>
      <geometry>
        <mesh filename="xela/allegro/link_0.0_ext.STL"/>
      </geometry>
      <material name="grey"/>
    </visual>
    <collision>
      <geometry>
        <box size="0.0196 0.0275 0.0164"/>
      </geometry>
      <origin rpy="0 0 0" xyz="0 0 0.011200000000000002"/>
    </collision>
    <inertial>
      <mass value="0.0127"/>
      <origin rpy="0 0 0" xyz="0 0 0"/>
      <inertia ixx="1.138e-06" ixy="1.27e-10" ixz="4.83e-09" iyy="6.683e-07" iyz="0.0" izz="0.0010001160000000001"/>
    </inertial>
  </link>
  <joint name="allegro_hand_jaka_finger_finger_joint_4" type="revolute">
    <axis xyz="0 0 1"/>
    <limit effort="30" lower="-0.47" upper="0.47" velocity="0.5"/>
    <parent link="allegro_hand_base_link"/>
    <child link="allegro_hand_jaka_finger_finger_link_4"/>
    <origin rpy="0.0 0 0" xyz="0 0 0.0007"/>
  </joint>
  <link name="allegro_hand_jaka_finger_finger_link_5">
    <visual>
      <geometry>
        <mesh filename="xela/allegro/link_1.0.stl"/>
      </geometry>
      <material name="black"/>
    </visual>
    <collision>
      <geometry>
        <mesh filename="xela/allegro/link_1.0.stl"/>
        <!-- <box size="0.0196 0.0275 0.0164"/> -->
      </geometry>
      <!-- <origin rpy="0 0 0" xyz="0 0 0.0082"/> -->
    </collision>
    <inertial>
      <mass value="0.809"/>
      <origin rpy="0 0 0" xyz="0 0 0"/>
      <inertia ixx="7.95654166667e-05" ixy="1.7199e-05" ixz="8.75875e-06" iyy="0.0010247088833333" iyz="2.413125e-05" izz="7.95654166667e-05"/>
    </inertial>
  </link>
  <!--covers are always with sensors-->
  <link name="allegro_hand_jaka_finger_finger_link_5_cover">
    <visual>
      <geometry>
        <mesh filename="xela/allegro/link_1_cover.stl"/>
      </geometry>
      <material name="black"/>
    </visual>
    <!-- <collision>
      <geometry>
        <mesh filename="xela/allegro/link_1_cover.stl"/>
      </geometry>
    </collision> -->
    <!--As link is fixed, inertias will be inside the main link-->
  </link>
  <joint name="allegro_hand_jaka_finger_finger_link_5_cover_joint" type="fixed">
    <origin rpy="0.0 0.0 0.0" xyz="0.0 0.0 0.0"/>
    <parent link="allegro_hand_jaka_finger_finger_link_5"/>
    <child link="allegro_hand_jaka_finger_finger_link_5_cover"/>
  </joint>
  <joint name="allegro_hand_jaka_finger_finger_joint_5" type="revolute">
    <limit effort="30" lower="-0.19599999999999998" upper="1.6099999999999999" velocity="0.5"/>
    <axis xyz="0 1 0"/>
    <parent link="allegro_hand_jaka_finger_finger_link_4"/>
    <child link="allegro_hand_jaka_finger_finger_link_5"/>
    <origin xyz="0 0 0.0204"/>
    <!-- New height on fingers -->
  </joint>
  <link name="allegro_hand_jaka_finger_finger_link_6">
    <visual>
      <geometry>
        <mesh filename="xela/allegro/link_2.0.stl"/>
      </geometry>
      <material name="black"/>
    </visual>
    <collision>
      <geometry>
        <box size="0.0196 0.0275 0.054"/>
      </geometry>
      <origin rpy="0 0 0" xyz="0 0 0.027"/>
    </collision>
    <!--covers are always with sensors-->
    <inertial>
      <mass value="0.0447"/>
      <origin rpy="0 0 0" xyz="0 0 0"/>
      <inertia ixx="2.63979183333e-05" ixy="6.67968e-06" ixz="4.783625e-06" iyy="0.0010134948516667" iyz="9.372e-06" izz="2.63979183333e-05"/>
    </inertial>
  </link>
  <link name="allegro_hand_jaka_finger_finger_link_6_cover">
    <visual>
      <geometry>
        <mesh filename="xela/allegro/link_2_cover.stl"/>
      </geometry>
      <material name="black"/>
    </visual>
    <!-- <collision>
      <geometry>
        <mesh filename="xela/allegro/link_2_cover.stl"/>
      </geometry>
    </collision> -->
  </link>
  <joint name="allegro_hand_jaka_finger_finger_link_6_cover_joint" type="fixed">
    <origin rpy="0.0 0.0 0.0" xyz="0.0 0.0 0.0"/>
    <parent link="allegro_hand_jaka_finger_finger_link_6"/>
    <child link="allegro_hand_jaka_finger_finger_link_6_cover"/>
  </joint>
  <joint name="allegro_hand_jaka_finger_finger_joint_6" type="revolute">
    <axis xyz="0 1 0"/>
    <limit effort="30" lower="-0.17400000000000002" upper="1.7089999999999999" velocity="0.5"/>
    <parent link="allegro_hand_jaka_finger_finger_link_5"/>
    <child link="allegro_hand_jaka_finger_finger_link_6"/>
    <origin xyz="0 0 0.054"/>
  </joint>
  <link name="allegro_hand_jaka_finger_finger_link_7">
    <visual>
      <geometry>
        <mesh filename="xela/allegro/link_3.0.STL"/>
      </geometry>
      <material name="black"/>
    </visual>
    <collision>
      <geometry>
        <box size="0.0196 0.0275 0.026399999999999996"/>
      </geometry>
      <origin rpy="0 0 0" xyz="0 0 0.013199999999999998"/>
    </collision>
    <inertial>
      <mass value="0.0404"/>
      <origin rpy="0 0 0" xyz="0 0 0"/>
      <inertia ixx="4.701248e-06" ixy="1.255968e-06" ixz="1.2936e-06" iyy="0.001003649312" iyz="1.7622e-06" izz="4.701248e-06"/>
    </inertial>
  </link>
  <joint name="allegro_hand_jaka_finger_finger_joint_7" type="revolute">
    <axis xyz="0 1 0"/>
    <limit effort="30" lower="-0.227" upper="1.6179999999999999" velocity="0.5"/>
    <parent link="allegro_hand_jaka_finger_finger_link_6"/>
    <child link="allegro_hand_jaka_finger_finger_link_7"/>
    <origin xyz="0 0.0 0.0384"/>
  </joint>
  <joint name="allegro_hand_jaka_finger_finger_1_aftc_fixed" type="fixed">
    <origin rpy="1.5707963267948966 0.0 1.5707963267948966" xyz="-0.013 0.0 0.016"/>
    <parent link="allegro_hand_jaka_finger_finger_link_7"/>
    <child link="allegro_hand_jaka_finger_finger_1_aftc_base_link"/>
  </joint>
  <link name="allegro_hand_jaka_finger_finger_1_aftc_base_link">
    <collision>
      <origin rpy="0 0 0" xyz="0 0 0"/>
      <geometry>
        <mesh filename="xela/ft_c.stl"/>
      </geometry>
    </collision>
    <visual>
      <origin rpy="0 0 0" xyz="0 0 0"/>
      <geometry>
        <mesh filename="xela/ft_c.stl"/>
      </geometry>
      <material name="black"/>
    </visual>
  </link>
  <link name="allegro_hand_kusuri_finger_finger_link_8">
    <visual>
      <geometry>
        <mesh filename="xela/allegro/link_0.0_ext.STL"/>
      </geometry>
      <material name="grey"/>
    </visual>
    <collision>
      <geometry>
        <box size="0.0196 0.0275 0.0164"/>
      </geometry>
      <origin rpy="0 0 0" xyz="0 0 0.011200000000000002"/>
    </collision>
    <inertial>
      <mass value="0.0127"/>
      <origin rpy="0 0 0" xyz="0 0 0"/>
      <inertia ixx="1.138e-06" ixy="1.27e-10" ixz="4.83e-09" iyy="6.683e-07" iyz="0.0" izz="0.0010001160000000001"/>
    </inertial>
  </link>
  <joint name="allegro_hand_kusuri_finger_finger_joint_8" type="revolute">
    <axis xyz="0 0 1"/>
    <limit effort="30" lower="-0.47" upper="0.47" velocity="0.5"/>
    <parent link="allegro_hand_base_link"/>
    <child link="allegro_hand_kusuri_finger_finger_link_8"/>
    <origin rpy="0.08726646259971647 0 0" xyz="0 -0.0435 -0.001542"/>
  </joint>
  <link name="allegro_hand_kusuri_finger_finger_link_9">
    <visual>
      <geometry>
        <mesh filename="xela/allegro/link_1.0.stl"/>
      </geometry>
      <material name="black"/>
    </visual>
    <collision>
      <geometry>
        <mesh filename="xela/allegro/link_1.0.stl"/>
        <!-- <box size="0.0196 0.0275 0.0164"/> -->
      </geometry>
      <!-- <origin rpy="0 0 0" xyz="0 0 0.0082"/> -->
    </collision>
    <inertial>
      <mass value="0.809"/>
      <origin rpy="0 0 0" xyz="0 0 0"/>
      <inertia ixx="7.95654166667e-05" ixy="1.7199e-05" ixz="8.75875e-06" iyy="0.0010247088833333" iyz="2.413125e-05" izz="7.95654166667e-05"/>
    </inertial>
  </link>
  <!--covers are always with sensors-->
  <link name="allegro_hand_kusuri_finger_finger_link_9_cover">
    <visual>
      <geometry>
        <mesh filename="xela/allegro/link_1_cover.stl"/>
      </geometry>
      <material name="black"/>
    </visual>
    <!-- <collision>
      <geometry>
        <mesh filename="xela/allegro/link_1_cover.stl"/>
      </geometry>
    </collision> -->
    <!--As link is fixed, inertias will be inside the main link-->
  </link>
  <joint name="allegro_hand_kusuri_finger_finger_link_9_cover_joint" type="fixed">
    <origin rpy="0.0 0.0 0.0" xyz="0.0 0.0 0.0"/>
    <parent link="allegro_hand_kusuri_finger_finger_link_9"/>
    <child link="allegro_hand_kusuri_finger_finger_link_9_cover"/>
  </joint>
  <joint name="allegro_hand_kusuri_finger_finger_joint_9" type="revolute">
    <limit effort="30" lower="-0.19599999999999998" upper="1.6099999999999999" velocity="0.5"/>
    <axis xyz="0 1 0"/>
    <parent link="allegro_hand_kusuri_finger_finger_link_8"/>
    <child link="allegro_hand_kusuri_finger_finger_link_9"/>
    <origin xyz="0 0 0.0204"/>
    <!-- New height on fingers -->
  </joint>
  <link name="allegro_hand_kusuri_finger_finger_link_10">
    <visual>
      <geometry>
        <mesh filename="xela/allegro/link_2.0.stl"/>
      </geometry>
      <material name="black"/>
    </visual>
    <collision>
      <geometry>
        <box size="0.0196 0.0275 0.054"/>
      </geometry>
      <origin rpy="0 0 0" xyz="0 0 0.027"/>
    </collision>
    <!--covers are always with sensors-->
    <inertial>
      <mass value="0.0447"/>
      <origin rpy="0 0 0" xyz="0 0 0"/>
      <inertia ixx="2.63979183333e-05" ixy="6.67968e-06" ixz="4.783625e-06" iyy="0.0010134948516667" iyz="9.372e-06" izz="2.63979183333e-05"/>
    </inertial>
  </link>
  <link name="allegro_hand_kusuri_finger_finger_link_10_cover">
    <visual>
      <geometry>
        <mesh filename="xela/allegro/link_2_cover.stl"/>
      </geometry>
      <material name="black"/>
    </visual>
    <!-- <collision>
      <geometry>
        <mesh filename="xela/allegro/link_2_cover.stl"/>
      </geometry>
    </collision> -->
  </link>
  <joint name="allegro_hand_kusuri_finger_finger_link_10_cover_joint" type="fixed">
    <origin rpy="0.0 0.0 0.0" xyz="0.0 0.0 0.0"/>
    <parent link="allegro_hand_kusuri_finger_finger_link_10"/>
    <child link="allegro_hand_kusuri_finger_finger_link_10_cover"/>
  </joint>
  <joint name="allegro_hand_kusuri_finger_finger_joint_10" type="revolute">
    <axis xyz="0 1 0"/>
    <limit effort="30" lower="-0.17400000000000002" upper="1.7089999999999999" velocity="0.5"/>
    <parent link="allegro_hand_kusuri_finger_finger_link_9"/>
    <child link="allegro_hand_kusuri_finger_finger_link_10"/>
    <origin xyz="0 0 0.054"/>
  </joint>
  <link name="allegro_hand_kusuri_finger_finger_link_11">
    <visual>
      <geometry>
        <mesh filename="xela/allegro/link_3.0.STL"/>
      </geometry>
      <material name="black"/>
    </visual>
    <collision>
      <geometry>
        <box size="0.0196 0.0275 0.026399999999999996"/>
      </geometry>
      <origin rpy="0 0 0" xyz="0 0 0.013199999999999998"/>
    </collision>
    <inertial>
      <mass value="0.0404"/>
      <origin rpy="0 0 0" xyz="0 0 0"/>
      <inertia ixx="4.701248e-06" ixy="1.255968e-06" ixz="1.2936e-06" iyy="0.001003649312" iyz="1.7622e-06" izz="4.701248e-06"/>
    </inertial>
  </link>
  <joint name="allegro_hand_kusuri_finger_finger_joint_11" type="revolute">
    <axis xyz="0 1 0"/>
    <limit effort="30" lower="-0.227" upper="1.6179999999999999" velocity="0.5"/>
    <parent link="allegro_hand_kusuri_finger_finger_link_10"/>
    <child link="allegro_hand_kusuri_finger_finger_link_11"/>
    <origin xyz="0 0.0 0.0384"/>
  </joint>
  <joint name="allegro_hand_kusuri_finger_finger_2_aftc_fixed" type="fixed">
    <origin rpy="1.5707963267948966 0.0 1.5707963267948966" xyz="-0.013 0.0 0.016"/>
    <parent link="allegro_hand_kusuri_finger_finger_link_11"/>
    <child link="allegro_hand_kusuri_finger_finger_2_aftc_base_link"/>
  </joint>
  <link name="allegro_hand_kusuri_finger_finger_2_aftc_base_link">
    <collision>
      <origin rpy="0 0 0" xyz="0 0 0"/>
      <geometry>
        <mesh filename="xela/ft_c.stl"/>
      </geometry>
    </collision>
    <visual>
      <origin rpy="0 0 0" xyz="0 0 0"/>
      <geometry>
        <mesh filename="xela/ft_c.stl"/>
      </geometry>
      <material name="black"/>
    </visual>
  </link>
  <link name="allegro_hand_oya_finger_link_12">
    <visual>
      <geometry>
        <mesh filename="xela/allegro/link_12.0_right.STL"/>
      </geometry>
      <material name="grey"/>
    </visual>
    <collision>
      <geometry>
        <box size="0.0358 0.034 0.0455"/>
      </geometry>
      <origin rpy="0 0 0" xyz="-0.0179 0.009 0.0145"/>
    </collision>
    <inertial>
      <mass value="0.0176"/>
      <origin rpy="0 0 0" xyz="0 0 0"/>
      <inertia ixx="0.0010189273333333" ixy="7.16716e-06" ixz="5.35568e-06" iyy="1.43008213333e-05" iyz="6.8068e-06" izz="1.89273333333e-05"/>
    </inertial>
  </link>
  <joint name="allegro_hand_oya_finger_joint_12" type="revolute">
    <axis xyz="-1 0 0"/>
    <limit effort="30" lower="0.263" upper="1.396" velocity="0.5"/>
    <parent link="allegro_hand_base_link"/>
    <child link="allegro_hand_oya_finger_link_12"/>
    <origin rpy="0 -1.6580627893946132 -1.5707963267948966" xyz="-0.0182 0.019333 -0.045987"/>
  </joint>
  <link name="allegro_hand_oya_finger_link_13">
    <visual>
      <geometry>
        <mesh filename="xela/allegro/link_13.0.STL"/>
      </geometry>
      <material name="grey"/>
    </visual>
    <collision>
      <geometry>
        <box size="0.0196 0.0275 0.0177"/>
      </geometry>
      <origin rpy="0 0 0" xyz="0 0 0.00885"/>
    </collision>
    <inertial>
      <mass value="0.0127"/>
      <origin rpy="0 0 0" xyz="0 0 0"/>
      <inertia ixx="4.24250866667e-06" ixy="1.032087e-06" ixz="1.603525e-06" iyy="4.52362633333e-06" iyz="1.44808125e-06" izz="0.00100424250866667"/>
    </inertial>
  </link>
  <link name="allegro_hand_oya_finger_link_14_cover">
    <visual>
      <geometry>
        <mesh filename="xela/allegro/thumb_1_cover.stl"/>
      </geometry>
      <material name="black"/>
    </visual>
    <!-- <collision>
      <geometry>
        <mesh filename="xela/allegro/thumb_1_cover.stl"/>
      </geometry>
      <origin rpy="0 0 0" xyz="0 0 0"/>
    </collision> -->
  </link>
  <joint name="allegro_hand_oya_finger_link_14_cover_joint" type="fixed">
    <origin rpy="0.0 0.0 0.0" xyz="0.0 0.0 0.0"/>
    <parent link="allegro_hand_oya_finger_link_14"/>
    <child link="allegro_hand_oya_finger_link_14_cover"/>
  </joint>
  <joint name="allegro_hand_oya_finger_joint_13" type="revolute">
    <axis xyz="0 0 1"/>
    <limit effort="30" lower="-0.10499999999999998" upper="1.1629999999999998" velocity="0.5"/>
    <parent link="allegro_hand_oya_finger_link_12"/>
    <child link="allegro_hand_oya_finger_link_13"/>
    <origin xyz="-0.027 0.005 0.0399"/>
  </joint>
  <link name="allegro_hand_oya_finger_link_14">
    <visual>
      <geometry>
        <mesh filename="xela/allegro/thumb_1.0.stl"/>
      </geometry>
      <material name="black"/>
    </visual>
    <collision>
      <geometry>
        <box size="0.0196 0.0275 0.0514"/>
      </geometry>
      <origin rpy="0 0 0" xyz="0 0 0.0257"/>
    </collision>
    <!--covers are always with sensors-->
    <inertial>
      <mass value="0.0457"/>
      <origin rpy="0 0 0" xyz="0 0 0"/>
      <inertia ixx="4.30439933333e-05" ixy="9.57068e-06" ixz="5.1205e-06" iyy="0.0010144451933333" iyz="1.342825e-05" izz="4.30439933333e-05"/>
    </inertial>
  </link>
  <link name="allegro_hand_oya_finger_link_15_cover">
    <visual>
      <geometry>
        <mesh filename="xela/allegro/thumb_2_cover.stl"/>
      </geometry>
      <material name="black"/>
    </visual>
    <!-- <collision>
      <geometry>
        <mesh filename="xela/allegro/thumb_2_cover.stl"/>
      </geometry>
      <origin rpy="0 0 0" xyz="0 0 0"/>
    </collision> -->
  </link>
  <joint name="allegro_hand_oya_finger_link_15_cover_joint" type="fixed">
    <origin rpy="0.0 0.0 0.0" xyz="0.0 0.0 0.0"/>
    <parent link="allegro_hand_oya_finger_link_15"/>
    <child link="allegro_hand_oya_finger_link_15_cover"/>
  </joint>
  <joint name="allegro_hand_oya_finger_joint_14" type="revolute">
    <axis xyz="0 1 0"/>
    <limit effort="30" lower="-0.18899999999999997" upper="1.644" velocity="0.5"/>
    <parent link="allegro_hand_oya_finger_link_13"/>
    <child link="allegro_hand_oya_finger_link_14"/>
    <origin xyz="0 0 0.0177"/>
  </joint>
  <link name="allegro_hand_oya_finger_link_15">
    <visual>
      <geometry>
        <mesh filename="xela/allegro/thumb_2.0.stl"/>
      </geometry>
      <material name="black"/>
    </visual>
    <collision>
      <geometry>
        <box size="0.0196 0.0275 0.042300000000000004"/>
      </geometry>
      <origin rpy="0 0 0" xyz="0 0 0.021150000000000002"/>
    </collision>
    <inertial>
      <mass value="0.0753"/>
      <origin rpy="0 0 0" xyz="0 0 0"/>
      <inertia ixx="2.90e-05" ixy="0.0" ixz="0.0" iyy="0.001000968" iyz="0.0" izz="6.88e-06"/>
    </inertial>
  </link>
  <joint name="allegro_hand_oya_finger_joint_15" type="revolute">
    <axis xyz="0 1 0"/>
    <limit effort="30" lower="-0.162" upper="1.7189999999999999" velocity="0.5"/>
    <parent link="allegro_hand_oya_finger_link_14"/>
    <child link="allegro_hand_oya_finger_link_15"/>
    <origin xyz="0 0 0.0514"/>
  </joint>
  <joint name="allegro_hand_oya_finger_3_aftc_fixed" type="fixed">
    <origin rpy="1.5707963267948966 0.0 1.5707963267948966" xyz="-0.013 0.0 0.0315"/>
    <parent link="allegro_hand_oya_finger_link_15"/>
    <child link="allegro_hand_oya_finger_3_aftc_base_link"/>
  </joint>
  <link name="allegro_hand_oya_finger_3_aftc_base_link">
    <collision>
      <origin rpy="0 0 0" xyz="0 0 0"/>
      <geometry>
        <mesh filename="xela/ft_c.stl"/>
      </geometry>
    </collision>
    <visual>
      <origin rpy="0 0 0" xyz="0 0 0"/>
      <geometry>
        <mesh filename="xela/ft_c.stl"/>
      </geometry>
      <material name="black"/>
    </visual>
  </link>
</robot>