<?xml version="1.0" ?>
<!-- =================================================================================== -->
<!-- |    This document was autogenerated by xacro from allegro_hand_right.xacro       | -->
<!-- |    EDITING THIS FILE BY HAND IS NOT RECOMMENDED                                 | -->
<!-- =================================================================================== -->
<robot name="allegro_hand_right">
  <!-- Rviz colors -->
  <material name="black">
    <color rgba="0.2 0.2 0.2 0.8"/>
    <!-- Slight transparency to make more visible -->
  </material>
  <material name="blue">
    <color rgba="0.0 0.0 0.8 1.0"/>
  </material>
  <material name="green">
    <color rgba="0.0 0.8 0.0 1.0"/>
  </material>
  <material name="grey">
    <color rgba="0.2 0.2 0.2 1.0"/>
  </material>
  <material name="orange">
    <color rgba="1.0 0.4235294117647059 0.0392156862745098 1.0"/>
  </material>
  <material name="brown">
    <color rgba="0.6470588235294118 0.16470588235294117 0.16470588235294117 1.0"/>
  </material>
  <material name="red">
    <color rgba="0.8 0.0 0.0 1.0"/>
  </material>
  <material name="white">
    <color rgba="1.0 1.0 1.0 1.0"/>
  </material>
  <link name="world"/>
  <link name="palm_link">
    <visual>
      <geometry>
        <mesh filename="package://xela_models/mesh/allegro/base.stl"/>
      </geometry>
      <origin rpy="0 0 0" xyz="0 0 0 "/>
      <material name="cyan">
        <color rgba="0.0 1.0 1.0 1"/>
      </material>
    </visual>
    <collision>
      <origin rpy="0 0 0" xyz="-0.009300 0 -0.0475"/>
      <geometry>
        <box size="0.0408 0.1130 0.095"/>
      </geometry>
    </collision>
    <inertial>
      <mass value="0.4288"/>
      <origin rpy="0 0 0" xyz="0 0 0"/>
      <inertia ixx="2.04e-03" ixy="8.58e-06" ixz="8.58e-06" iyy="1.23e-03" iyz="0.0" izz="1.25e-03"/>
    </inertial>
  </link>
  <joint name="ahr_fixed" type="fixed">
    <origin rpy="0.0 0.0 0.0" xyz="0.0 0.0 0.0"/>
    <parent link="world"/>
    <child link="palm_link"/>
  </joint>
  <joint name="ahr_palm_1_4x6_fixed" type="fixed">
    <origin rpy="1.5707963267948966 0.0 1.5707963267948966" xyz="0.013 -0.051 -0.0365"/>
    <parent link="palm_link"/>
    <child link="ahr_palm_1_4x6_palm_link"/>
  </joint>
  <link name="ahr_palm_1_4x6_palm_link">
    <collision>
      <origin rpy="0 0 0" xyz="0 0 0"/>
      <geometry>
        <mesh filename="package://xela_models/mesh/4x6.stl"/>
      </geometry>
    </collision>
    <visual>
      <origin rpy="0 0 0" xyz="0 0 0"/>
      <geometry>
        <mesh filename="package://xela_models/mesh/4x6.stl"/>
      </geometry>
      <material name="brown"/>
    </visual>
  </link>
  <joint name="ahr_palm_2_4x6_fixed" type="fixed">
    <origin rpy="1.5707963267948966 3.141592653589793 1.5707963267948966" xyz="0.013 0.0523 -0.005"/>
    <parent link="palm_link"/>
    <child link="ahr_palm_2_4x6_palm_link"/>
  </joint>
  <link name="ahr_palm_2_4x6_palm_link">
    <collision>
      <origin rpy="0 0 0" xyz="0 0 0"/>
      <geometry>
        <mesh filename="package://xela_models/mesh/4x6.stl"/>
      </geometry>
    </collision>
    <visual>
      <origin rpy="0 0 0" xyz="0 0 0"/>
      <geometry>
        <mesh filename="package://xela_models/mesh/4x6.stl"/>
      </geometry>
      <material name="brown"/>
    </visual>
  </link>
  <joint name="ahr_palm_3_4x6_fixed" type="fixed">
    <origin rpy="1.5707963267948966 0.0 1.5707963267948966" xyz="0.013 -0.051 -0.068"/>
    <parent link="palm_link"/>
    <child link="ahr_palm_3_4x6_palm_link"/>
  </joint>
  <link name="ahr_palm_3_4x6_palm_link">
    <collision>
      <origin rpy="0 0 0" xyz="0 0 0"/>
      <geometry>
        <mesh filename="package://xela_models/mesh/4x6.stl"/>
      </geometry>
    </collision>
    <visual>
      <origin rpy="0 0 0" xyz="0 0 0"/>
      <geometry>
        <mesh filename="package://xela_models/mesh/4x6.stl"/>
      </geometry>
      <material name="brown"/>
    </visual>
  </link>
  <link name="link_0">
    <visual>
      <geometry>
        <mesh filename="package://xela_models/mesh/allegro/link_0.0_ext.STL"/>
      </geometry>
      <material name="grey"/>
    </visual>
    <collision>
      <geometry>
        <box size="0.0196 0.0275 0.0164"/>
      </geometry>
      <origin rpy="0 0 0" xyz="0 0 0.011200000000000002"/>
    </collision>
    <inertial>
      <mass value="0.0127"/>
      <origin rpy="0 0 0" xyz="0 0 0"/>
      <inertia ixx="1.38e-07" ixy="1.27e-10" ixz="4.83e-09" iyy="6.83e-08" iyz="0.0" izz="1.16e-07"/>
    </inertial>
  </link>
  <joint name="joint_0" type="revolute">
    <axis xyz="0 0 1"/>
    <limit effort="15" lower="-0.47" upper="0.47" velocity="7"/>
    <parent link="palm_link"/>
    <child link="link_0"/>
    <origin rpy="-0.08726646259971647 0 0" xyz="0 0.0435 -0.001542"/>
  </joint>
  <link name="link_1">
    <visual>
      <geometry>
        <mesh filename="package://xela_models/mesh/allegro/link_1.0.stl"/>
      </geometry>
      <material name="black"/>
    </visual>
    <collision>
      <geometry>
        <box size="0.0196 0.0275 0.0164"/>
      </geometry>
      <origin rpy="0 0 0" xyz="0 0 0.0082"/>
    </collision>
    <inertial>
      <mass value="0.0809"/>
      <origin rpy="0 0 0" xyz="0 0 0"/>
      <inertia ixx="1.75e-05" ixy="0.0" ixz="5.66e-08" iyy="1.80e-05" iyz="0.0" izz="4.60e-06"/>
    </inertial>
  </link>
  <!--covers are always with sensors-->
  <link name="link_1_cover">
    <visual>
      <geometry>
        <mesh filename="package://xela_models/mesh/allegro/link_1_cover.stl"/>
      </geometry>
      <material name="red"/>
    </visual>
    <collision>
      <geometry>
        <mesh filename="package://xela_models/mesh/allegro/link_1_cover.stl"/>
      </geometry>
      <origin rpy="0 0 0" xyz="0 0 0.00885"/>
    </collision>
    <!--As link is fixed, inertias will be inside the main link-->
  </link>
  <joint name="link_1_cover_joint" type="fixed">
    <origin rpy="0.0 0.0 0.0" xyz="0.0 0.0 0.0"/>
    <parent link="link_1"/>
    <child link="link_1_cover"/>
  </joint>
  <joint name="link_1A_4x4_fixed" type="fixed">
    <origin rpy="0.0 -1.5707963267948966 3.141592653589793" xyz="0.0108 0.012 0.033"/>
    <parent link="link_1"/>
    <child link="link_1A_4x4_palm_link"/>
  </joint>
  <link name="link_1A_4x4_palm_link">
    <collision>
      <origin rpy="0 0 0" xyz="0 0 0"/>
      <geometry>
        <mesh filename="package://xela_models/mesh/4x4.stl"/>
      </geometry>
    </collision>
    <visual>
      <origin rpy="0 0 0" xyz="0 0 0"/>
      <geometry>
        <mesh filename="package://xela_models/mesh/4x4.stl"/>
      </geometry>
      <material name="blue"/>
    </visual>
  </link>
  <joint name="link_1B_4x4_fixed" type="fixed">
    <origin rpy="0.0 1.5707963267948966 0.0" xyz="0.0108 -0.012 0.021"/>
    <parent link="link_1"/>
    <child link="link_1B_4x4_palm_link"/>
  </joint>
  <link name="link_1B_4x4_palm_link">
    <collision>
      <origin rpy="0 0 0" xyz="0 0 0"/>
      <geometry>
        <mesh filename="package://xela_models/mesh/4x4.stl"/>
      </geometry>
    </collision>
    <visual>
      <origin rpy="0 0 0" xyz="0 0 0"/>
      <geometry>
        <mesh filename="package://xela_models/mesh/4x4.stl"/>
      </geometry>
      <material name="blue"/>
    </visual>
  </link>
  <joint name="joint_1" type="revolute">
    <limit effort="15" lower="-0.19599999999999998" upper="1.6099999999999999" velocity="7"/>
    <axis xyz="0 1 0"/>
    <parent link="link_0"/>
    <child link="link_1"/>
    <origin xyz="0 0 0.0189"/>
    <!-- New height on fingers -->
  </joint>
  <link name="link_2">
    <visual>
      <geometry>
        <mesh filename="package://xela_models/mesh/allegro/link_2.0.stl"/>
      </geometry>
      <material name="black"/>
    </visual>
    <collision>
      <geometry>
        <box size="0.0196 0.0275 0.054"/>
      </geometry>
      <origin rpy="0 0 0" xyz="0 0 0.027"/>
    </collision>
    <!--covers are always with sensors-->
    <inertial>
      <mass value="0.0447"/>
      <origin rpy="0 0 0" xyz="0 0 0"/>
      <inertia ixx="3.80e-07" ixy="0.0" ixz="7.15e-09" iyy="2.26e-07" iyz="1.34e-09" izz="1.86e-07"/>
    </inertial>
  </link>
  <link name="link_2_cover">
    <visual>
      <geometry>
        <mesh filename="package://xela_models/mesh/allegro/link_2_cover.stl"/>
      </geometry>
      <material name="red"/>
    </visual>
    <collision>
      <geometry>
        <mesh filename="package://xela_models/mesh/allegro/link_2_cover.stl"/>
      </geometry>
      <origin rpy="0 0 0" xyz="0 0 0.0257"/>
    </collision>
  </link>
  <joint name="link_2_cover_joint" type="fixed">
    <origin rpy="0.0 0.0 0.0" xyz="0.0 0.0 0.0"/>
    <parent link="link_2"/>
    <child link="link_2_cover"/>
  </joint>
  <joint name="link_2_4x4_fixed" type="fixed">
    <origin rpy="0.0 1.5707963267948966 0.0" xyz="0.01 -0.012 0.0445"/>
    <parent link="link_2"/>
    <child link="link_2_4x4_palm_link"/>
  </joint>
  <link name="link_2_4x4_palm_link">
    <collision>
      <origin rpy="0 0 0" xyz="0 0 0"/>
      <geometry>
        <mesh filename="package://xela_models/mesh/4x4.stl"/>
      </geometry>
    </collision>
    <visual>
      <origin rpy="0 0 0" xyz="0 0 0"/>
      <geometry>
        <mesh filename="package://xela_models/mesh/4x4.stl"/>
      </geometry>
      <material name="blue"/>
    </visual>
  </link>
  <joint name="joint_2" type="revolute">
    <axis xyz="0 1 0"/>
    <limit effort="15" lower="-0.17400000000000002" upper="1.7089999999999999" velocity="7"/>
    <parent link="link_1"/>
    <child link="link_2"/>
    <origin xyz="0 0 0.054"/>
  </joint>
  <link name="link_3">
    <visual>
      <geometry>
        <mesh filename="package://xela_models/mesh/allegro/link_3.0.STL"/>
      </geometry>
      <material name="black"/>
    </visual>
    <collision>
      <geometry>
        <box size="0.0196 0.0275 0.026399999999999996"/>
      </geometry>
      <origin rpy="0 0 0" xyz="0 0 0.013199999999999998"/>
    </collision>
    <inertial>
      <mass value="0.0404"/>
      <origin rpy="0 0 0" xyz="0 0 0"/>
      <inertia ixx="3.64e-06" ixy="0.0" ixz="0.0" iyy="3.33e-06" iyz="0.0" izz="1.92e-06"/>
    </inertial>
  </link>
  <joint name="joint_3" type="revolute">
    <axis xyz="0 1 0"/>
    <limit effort="15" lower="-0.227" upper="1.6179999999999999" velocity="7"/>
    <parent link="link_2"/>
    <child link="link_3"/>
    <origin xyz="0 0.0 0.0384"/>
  </joint>
  <joint name="0aftc_fixed" type="fixed">
    <origin rpy="1.5707963267948966 0.0 1.5707963267948966" xyz="-0.013 0.0 0.016"/>
    <parent link="link_3"/>
    <child link="0aftc_palm_link"/>
  </joint>
  <link name="0aftc_palm_link">
    <collision>
      <origin rpy="0 0 0" xyz="0 0 0"/>
      <geometry>
        <mesh filename="package://xela_models/mesh/ft_c.stl"/>
      </geometry>
    </collision>
    <visual>
      <origin rpy="0 0 0" xyz="0 0 0"/>
      <geometry>
        <mesh filename="package://xela_models/mesh/ft_c.stl"/>
      </geometry>
      <material name="orange"/>
    </visual>
  </link>
  <link name="link_4">
    <visual>
      <geometry>
        <mesh filename="package://xela_models/mesh/allegro/link_0.0_ext.STL"/>
      </geometry>
      <material name="grey"/>
    </visual>
    <collision>
      <geometry>
        <box size="0.0196 0.0275 0.0164"/>
      </geometry>
      <origin rpy="0 0 0" xyz="0 0 0.011200000000000002"/>
    </collision>
    <inertial>
      <mass value="0.0127"/>
      <origin rpy="0 0 0" xyz="0 0 0"/>
      <inertia ixx="1.38e-07" ixy="1.27e-10" ixz="4.83e-09" iyy="6.83e-08" iyz="0.0" izz="1.16e-07"/>
    </inertial>
  </link>
  <joint name="joint_4" type="revolute">
    <axis xyz="0 0 1"/>
    <limit effort="15" lower="-0.47" upper="0.47" velocity="7"/>
    <parent link="palm_link"/>
    <child link="link_4"/>
    <origin rpy="0.0 0 0" xyz="0 0 0.0007"/>
  </joint>
  <link name="link_5">
    <visual>
      <geometry>
        <mesh filename="package://xela_models/mesh/allegro/link_1.0.stl"/>
      </geometry>
      <material name="black"/>
    </visual>
    <collision>
      <geometry>
        <box size="0.0196 0.0275 0.0164"/>
      </geometry>
      <origin rpy="0 0 0" xyz="0 0 0.0082"/>
    </collision>
    <inertial>
      <mass value="0.0809"/>
      <origin rpy="0 0 0" xyz="0 0 0"/>
      <inertia ixx="1.75e-05" ixy="0.0" ixz="5.66e-08" iyy="1.80e-05" iyz="0.0" izz="4.60e-06"/>
    </inertial>
  </link>
  <!--covers are always with sensors-->
  <link name="link_5_cover">
    <visual>
      <geometry>
        <mesh filename="package://xela_models/mesh/allegro/link_1_cover.stl"/>
      </geometry>
      <material name="red"/>
    </visual>
    <collision>
      <geometry>
        <mesh filename="package://xela_models/mesh/allegro/link_1_cover.stl"/>
      </geometry>
      <origin rpy="0 0 0" xyz="0 0 0.00885"/>
    </collision>
    <!--As link is fixed, inertias will be inside the main link-->
  </link>
  <joint name="link_5_cover_joint" type="fixed">
    <origin rpy="0.0 0.0 0.0" xyz="0.0 0.0 0.0"/>
    <parent link="link_5"/>
    <child link="link_5_cover"/>
  </joint>
  <joint name="link_5A_4x4_fixed" type="fixed">
    <origin rpy="0.0 -1.5707963267948966 3.141592653589793" xyz="0.0108 0.012 0.033"/>
    <parent link="link_5"/>
    <child link="link_5A_4x4_palm_link"/>
  </joint>
  <link name="link_5A_4x4_palm_link">
    <collision>
      <origin rpy="0 0 0" xyz="0 0 0"/>
      <geometry>
        <mesh filename="package://xela_models/mesh/4x4.stl"/>
      </geometry>
    </collision>
    <visual>
      <origin rpy="0 0 0" xyz="0 0 0"/>
      <geometry>
        <mesh filename="package://xela_models/mesh/4x4.stl"/>
      </geometry>
      <material name="blue"/>
    </visual>
  </link>
  <joint name="link_5B_4x4_fixed" type="fixed">
    <origin rpy="0.0 1.5707963267948966 0.0" xyz="0.0108 -0.012 0.021"/>
    <parent link="link_5"/>
    <child link="link_5B_4x4_palm_link"/>
  </joint>
  <link name="link_5B_4x4_palm_link">
    <collision>
      <origin rpy="0 0 0" xyz="0 0 0"/>
      <geometry>
        <mesh filename="package://xela_models/mesh/4x4.stl"/>
      </geometry>
    </collision>
    <visual>
      <origin rpy="0 0 0" xyz="0 0 0"/>
      <geometry>
        <mesh filename="package://xela_models/mesh/4x4.stl"/>
      </geometry>
      <material name="blue"/>
    </visual>
  </link>
  <joint name="joint_5" type="revolute">
    <limit effort="15" lower="-0.19599999999999998" upper="1.6099999999999999" velocity="7"/>
    <axis xyz="0 1 0"/>
    <parent link="link_4"/>
    <child link="link_5"/>
    <origin xyz="0 0 0.0189"/>
    <!-- New height on fingers -->
  </joint>
  <link name="link_6">
    <visual>
      <geometry>
        <mesh filename="package://xela_models/mesh/allegro/link_2.0.stl"/>
      </geometry>
      <material name="black"/>
    </visual>
    <collision>
      <geometry>
        <box size="0.0196 0.0275 0.054"/>
      </geometry>
      <origin rpy="0 0 0" xyz="0 0 0.027"/>
    </collision>
    <!--covers are always with sensors-->
    <inertial>
      <mass value="0.0447"/>
      <origin rpy="0 0 0" xyz="0 0 0"/>
      <inertia ixx="3.80e-07" ixy="0.0" ixz="7.15e-09" iyy="2.26e-07" iyz="1.34e-09" izz="1.86e-07"/>
    </inertial>
  </link>
  <link name="link_6_cover">
    <visual>
      <geometry>
        <mesh filename="package://xela_models/mesh/allegro/link_2_cover.stl"/>
      </geometry>
      <material name="red"/>
    </visual>
    <collision>
      <geometry>
        <mesh filename="package://xela_models/mesh/allegro/link_2_cover.stl"/>
      </geometry>
      <origin rpy="0 0 0" xyz="0 0 0.0257"/>
    </collision>
  </link>
  <joint name="link_6_cover_joint" type="fixed">
    <origin rpy="0.0 0.0 0.0" xyz="0.0 0.0 0.0"/>
    <parent link="link_6"/>
    <child link="link_6_cover"/>
  </joint>
  <joint name="link_6_4x4_fixed" type="fixed">
    <origin rpy="0.0 1.5707963267948966 0.0" xyz="0.01 -0.012 0.0445"/>
    <parent link="link_6"/>
    <child link="link_6_4x4_palm_link"/>
  </joint>
  <link name="link_6_4x4_palm_link">
    <collision>
      <origin rpy="0 0 0" xyz="0 0 0"/>
      <geometry>
        <mesh filename="package://xela_models/mesh/4x4.stl"/>
      </geometry>
    </collision>
    <visual>
      <origin rpy="0 0 0" xyz="0 0 0"/>
      <geometry>
        <mesh filename="package://xela_models/mesh/4x4.stl"/>
      </geometry>
      <material name="blue"/>
    </visual>
  </link>
  <joint name="joint_6" type="revolute">
    <axis xyz="0 1 0"/>
    <limit effort="15" lower="-0.17400000000000002" upper="1.7089999999999999" velocity="7"/>
    <parent link="link_5"/>
    <child link="link_6"/>
    <origin xyz="0 0 0.054"/>
  </joint>
  <link name="link_7">
    <visual>
      <geometry>
        <mesh filename="package://xela_models/mesh/allegro/link_3.0.STL"/>
      </geometry>
      <material name="black"/>
    </visual>
    <collision>
      <geometry>
        <box size="0.0196 0.0275 0.026399999999999996"/>
      </geometry>
      <origin rpy="0 0 0" xyz="0 0 0.013199999999999998"/>
    </collision>
    <inertial>
      <mass value="0.0404"/>
      <origin rpy="0 0 0" xyz="0 0 0"/>
      <inertia ixx="3.64e-06" ixy="0.0" ixz="0.0" iyy="3.33e-06" iyz="0.0" izz="1.92e-06"/>
    </inertial>
  </link>
  <joint name="joint_7" type="revolute">
    <axis xyz="0 1 0"/>
    <limit effort="15" lower="-0.227" upper="1.6179999999999999" velocity="7"/>
    <parent link="link_6"/>
    <child link="link_7"/>
    <origin xyz="0 0.0 0.0384"/>
  </joint>
  <joint name="1aftc_fixed" type="fixed">
    <origin rpy="1.5707963267948966 0.0 1.5707963267948966" xyz="-0.013 0.0 0.016"/>
    <parent link="link_7"/>
    <child link="1aftc_palm_link"/>
  </joint>
  <link name="1aftc_palm_link">
    <collision>
      <origin rpy="0 0 0" xyz="0 0 0"/>
      <geometry>
        <mesh filename="package://xela_models/mesh/ft_c.stl"/>
      </geometry>
    </collision>
    <visual>
      <origin rpy="0 0 0" xyz="0 0 0"/>
      <geometry>
        <mesh filename="package://xela_models/mesh/ft_c.stl"/>
      </geometry>
      <material name="orange"/>
    </visual>
  </link>
  <link name="link_8">
    <visual>
      <geometry>
        <mesh filename="package://xela_models/mesh/allegro/link_0.0_ext.STL"/>
      </geometry>
      <material name="grey"/>
    </visual>
    <collision>
      <geometry>
        <box size="0.0196 0.0275 0.0164"/>
      </geometry>
      <origin rpy="0 0 0" xyz="0 0 0.011200000000000002"/>
    </collision>
    <inertial>
      <mass value="0.0127"/>
      <origin rpy="0 0 0" xyz="0 0 0"/>
      <inertia ixx="1.38e-07" ixy="1.27e-10" ixz="4.83e-09" iyy="6.83e-08" iyz="0.0" izz="1.16e-07"/>
    </inertial>
  </link>
  <joint name="joint_8" type="revolute">
    <axis xyz="0 0 1"/>
    <limit effort="15" lower="-0.47" upper="0.47" velocity="7"/>
    <parent link="palm_link"/>
    <child link="link_8"/>
    <origin rpy="0.08726646259971647 0 0" xyz="0 -0.0435 -0.001542"/>
  </joint>
  <link name="link_9">
    <visual>
      <geometry>
        <mesh filename="package://xela_models/mesh/allegro/link_1.0.stl"/>
      </geometry>
      <material name="black"/>
    </visual>
    <collision>
      <geometry>
        <box size="0.0196 0.0275 0.0164"/>
      </geometry>
      <origin rpy="0 0 0" xyz="0 0 0.0082"/>
    </collision>
    <inertial>
      <mass value="0.0809"/>
      <origin rpy="0 0 0" xyz="0 0 0"/>
      <inertia ixx="1.75e-05" ixy="0.0" ixz="5.66e-08" iyy="1.80e-05" iyz="0.0" izz="4.60e-06"/>
    </inertial>
  </link>
  <!--covers are always with sensors-->
  <link name="link_9_cover">
    <visual>
      <geometry>
        <mesh filename="package://xela_models/mesh/allegro/link_1_cover.stl"/>
      </geometry>
      <material name="red"/>
    </visual>
    <collision>
      <geometry>
        <mesh filename="package://xela_models/mesh/allegro/link_1_cover.stl"/>
      </geometry>
      <origin rpy="0 0 0" xyz="0 0 0.00885"/>
    </collision>
    <!--As link is fixed, inertias will be inside the main link-->
  </link>
  <joint name="link_9_cover_joint" type="fixed">
    <origin rpy="0.0 0.0 0.0" xyz="0.0 0.0 0.0"/>
    <parent link="link_9"/>
    <child link="link_9_cover"/>
  </joint>
  <joint name="link_9A_4x4_fixed" type="fixed">
    <origin rpy="0.0 -1.5707963267948966 3.141592653589793" xyz="0.0108 0.012 0.033"/>
    <parent link="link_9"/>
    <child link="link_9A_4x4_palm_link"/>
  </joint>
  <link name="link_9A_4x4_palm_link">
    <collision>
      <origin rpy="0 0 0" xyz="0 0 0"/>
      <geometry>
        <mesh filename="package://xela_models/mesh/4x4.stl"/>
      </geometry>
    </collision>
    <visual>
      <origin rpy="0 0 0" xyz="0 0 0"/>
      <geometry>
        <mesh filename="package://xela_models/mesh/4x4.stl"/>
      </geometry>
      <material name="blue"/>
    </visual>
  </link>
  <joint name="link_9B_4x4_fixed" type="fixed">
    <origin rpy="0.0 1.5707963267948966 0.0" xyz="0.0108 -0.012 0.021"/>
    <parent link="link_9"/>
    <child link="link_9B_4x4_palm_link"/>
  </joint>
  <link name="link_9B_4x4_palm_link">
    <collision>
      <origin rpy="0 0 0" xyz="0 0 0"/>
      <geometry>
        <mesh filename="package://xela_models/mesh/4x4.stl"/>
      </geometry>
    </collision>
    <visual>
      <origin rpy="0 0 0" xyz="0 0 0"/>
      <geometry>
        <mesh filename="package://xela_models/mesh/4x4.stl"/>
      </geometry>
      <material name="blue"/>
    </visual>
  </link>
  <joint name="joint_9" type="revolute">
    <limit effort="15" lower="-0.19599999999999998" upper="1.6099999999999999" velocity="7"/>
    <axis xyz="0 1 0"/>
    <parent link="link_8"/>
    <child link="link_9"/>
    <origin xyz="0 0 0.0189"/>
    <!-- New height on fingers -->
  </joint>
  <link name="link_10">
    <visual>
      <geometry>
        <mesh filename="package://xela_models/mesh/allegro/link_2.0.stl"/>
      </geometry>
      <material name="black"/>
    </visual>
    <collision>
      <geometry>
        <box size="0.0196 0.0275 0.054"/>
      </geometry>
      <origin rpy="0 0 0" xyz="0 0 0.027"/>
    </collision>
    <!--covers are always with sensors-->
    <inertial>
      <mass value="0.0447"/>
      <origin rpy="0 0 0" xyz="0 0 0"/>
      <inertia ixx="3.80e-07" ixy="0.0" ixz="7.15e-09" iyy="2.26e-07" iyz="1.34e-09" izz="1.86e-07"/>
    </inertial>
  </link>
  <link name="link_10_cover">
    <visual>
      <geometry>
        <mesh filename="package://xela_models/mesh/allegro/link_2_cover.stl"/>
      </geometry>
      <material name="red"/>
    </visual>
    <collision>
      <geometry>
        <mesh filename="package://xela_models/mesh/allegro/link_2_cover.stl"/>
      </geometry>
      <origin rpy="0 0 0" xyz="0 0 0.0257"/>
    </collision>
  </link>
  <joint name="link_10_cover_joint" type="fixed">
    <origin rpy="0.0 0.0 0.0" xyz="0.0 0.0 0.0"/>
    <parent link="link_10"/>
    <child link="link_10_cover"/>
  </joint>
  <joint name="link_10_4x4_fixed" type="fixed">
    <origin rpy="0.0 1.5707963267948966 0.0" xyz="0.01 -0.012 0.0445"/>
    <parent link="link_10"/>
    <child link="link_10_4x4_palm_link"/>
  </joint>
  <link name="link_10_4x4_palm_link">
    <collision>
      <origin rpy="0 0 0" xyz="0 0 0"/>
      <geometry>
        <mesh filename="package://xela_models/mesh/4x4.stl"/>
      </geometry>
    </collision>
    <visual>
      <origin rpy="0 0 0" xyz="0 0 0"/>
      <geometry>
        <mesh filename="package://xela_models/mesh/4x4.stl"/>
      </geometry>
      <material name="blue"/>
    </visual>
  </link>
  <joint name="joint_10" type="revolute">
    <axis xyz="0 1 0"/>
    <limit effort="15" lower="-0.17400000000000002" upper="1.7089999999999999" velocity="7"/>
    <parent link="link_9"/>
    <child link="link_10"/>
    <origin xyz="0 0 0.054"/>
  </joint>
  <link name="link_11">
    <visual>
      <geometry>
        <mesh filename="package://xela_models/mesh/allegro/link_3.0.STL"/>
      </geometry>
      <material name="black"/>
    </visual>
    <collision>
      <geometry>
        <box size="0.0196 0.0275 0.026399999999999996"/>
      </geometry>
      <origin rpy="0 0 0" xyz="0 0 0.013199999999999998"/>
    </collision>
    <inertial>
      <mass value="0.0404"/>
      <origin rpy="0 0 0" xyz="0 0 0"/>
      <inertia ixx="3.64e-06" ixy="0.0" ixz="0.0" iyy="3.33e-06" iyz="0.0" izz="1.92e-06"/>
    </inertial>
  </link>
  <joint name="joint_11" type="revolute">
    <axis xyz="0 1 0"/>
    <limit effort="15" lower="-0.227" upper="1.6179999999999999" velocity="7"/>
    <parent link="link_10"/>
    <child link="link_11"/>
    <origin xyz="0 0.0 0.0384"/>
  </joint>
  <joint name="2aftc_fixed" type="fixed">
    <origin rpy="1.5707963267948966 0.0 1.5707963267948966" xyz="-0.013 0.0 0.016"/>
    <parent link="link_11"/>
    <child link="2aftc_palm_link"/>
  </joint>
  <link name="2aftc_palm_link">
    <collision>
      <origin rpy="0 0 0" xyz="0 0 0"/>
      <geometry>
        <mesh filename="package://xela_models/mesh/ft_c.stl"/>
      </geometry>
    </collision>
    <visual>
      <origin rpy="0 0 0" xyz="0 0 0"/>
      <geometry>
        <mesh filename="package://xela_models/mesh/ft_c.stl"/>
      </geometry>
      <material name="orange"/>
    </visual>
  </link>
  <link name="link_12">
    <visual>
      <geometry>
        <mesh filename="package://xela_models/mesh/allegro/link_12.0_right.STL"/>
      </geometry>
      <material name="grey"/>
    </visual>
    <collision>
      <geometry>
        <box size="0.0358 0.034 0.0455"/>
      </geometry>
      <origin rpy="0 0 0" xyz="-0.0179 0.009 0.0145"/>
    </collision>
    <inertial>
      <mass value="0.0176"/>
      <origin rpy="0 0 0" xyz="0 0 0"/>
      <inertia ixx="3.36e-06" ixy="0.0" ixz="1.76e-08" iyy="3.84e-06" iyz="2.46e-07" izz="2.59e-06"/>
    </inertial>
  </link>
  <joint name="joint_12" type="revolute">
    <axis xyz="-1 0 0"/>
    <limit effort="15" lower="0.263" upper="1.396" velocity="7"/>
    <parent link="palm_link"/>
    <child link="link_12"/>
    <origin rpy="0 -1.6580627893946132 -1.5707963267948966" xyz="-0.0182 0.019333 -0.046487"/>
  </joint>
  <link name="link_13">
    <visual>
      <geometry>
        <mesh filename="package://xela_models/mesh/allegro/link_0.0_ext.STL"/>
        <!-- link_13.0.STL -->
      </geometry>
      <material name="grey"/>
    </visual>
    <collision>
      <geometry>
        <box size="0.0196 0.0275 0.0177"/>
      </geometry>
      <origin rpy="0 0 0" xyz="0 0 0.00885"/>
    </collision>
    <inertial>
      <mass value="0.0127"/>
      <origin rpy="0 0 0" xyz="0 0 0"/>
      <inertia ixx="1.38e-07" ixy="1.27e-10" ixz="4.83e-09" iyy="6.83e-08" iyz="0.0" izz="1.16e-07"/>
    </inertial>
  </link>
  <link name="link_14_cover">
    <visual>
      <geometry>
        <mesh filename="package://xela_models/mesh/allegro/thumb_1_cover.stl"/>
      </geometry>
      <material name="red"/>
    </visual>
    <collision>
      <geometry>
        <mesh filename="package://xela_models/mesh/allegro/thumb_1_cover.stl"/>
      </geometry>
      <origin rpy="0 0 0" xyz="0 0 0"/>
    </collision>
  </link>
  <joint name="link_14_cover_joint" type="fixed">
    <origin rpy="0.0 0.0 0.0" xyz="0.0 0.0 0.0"/>
    <parent link="link_14"/>
    <child link="link_14_cover"/>
  </joint>
  <joint name="joint_13" type="revolute">
    <axis xyz="0 0 1"/>
    <limit effort="15" lower="-0.10499999999999998" upper="1.1629999999999998" velocity="7"/>
    <parent link="link_12"/>
    <child link="link_13"/>
    <origin xyz="-0.027 0.005 0.0399"/>
  </joint>
  <link name="link_14">
    <visual>
      <geometry>
        <mesh filename="package://xela_models/mesh/allegro/thumb_1.0.stl"/>
      </geometry>
      <material name="black"/>
    </visual>
    <collision>
      <geometry>
        <box size="0.0196 0.0275 0.0514"/>
      </geometry>
      <origin rpy="0 0 0" xyz="0 0 0.0257"/>
    </collision>
    <!--covers are always with sensors-->
    <inertial>
      <mass value="0.0457"/>
      <origin rpy="0 0 0" xyz="0 0 0"/>
      <inertia ixx="3.20e-06" ixy="9.14e-09" ixz="1.46e-07" iyy="3.03e-06" iyz="0.0" izz="1.47e-06"/>
    </inertial>
  </link>
  <link name="link_15_cover">
    <visual>
      <geometry>
        <mesh filename="package://xela_models/mesh/allegro/thumb_2_cover.stl"/>
      </geometry>
      <material name="red"/>
    </visual>
    <collision>
      <geometry>
        <mesh filename="package://xela_models/mesh/allegro/thumb_2_cover.stl"/>
      </geometry>
      <origin rpy="0 0 0" xyz="0 0 0"/>
    </collision>
  </link>
  <joint name="link_15_cover_joint" type="fixed">
    <origin rpy="0.0 0.0 0.0" xyz="0.0 0.0 0.0"/>
    <parent link="link_15"/>
    <child link="link_15_cover"/>
  </joint>
  <joint name="link_14_4x4_fixed" type="fixed">
    <origin rpy="0.0 1.5707963267948966 0.0" xyz="0.011 -0.012 0.023"/>
    <parent link="link_14"/>
    <child link="link_14_4x4_palm_link"/>
  </joint>
  <link name="link_14_4x4_palm_link">
    <collision>
      <origin rpy="0 0 0" xyz="0 0 0"/>
      <geometry>
        <mesh filename="package://xela_models/mesh/4x4.stl"/>
      </geometry>
    </collision>
    <visual>
      <origin rpy="0 0 0" xyz="0 0 0"/>
      <geometry>
        <mesh filename="package://xela_models/mesh/4x4.stl"/>
      </geometry>
      <material name="blue"/>
    </visual>
  </link>
  <joint name="joint_14" type="revolute">
    <axis xyz="0 1 0"/>
    <limit effort="15" lower="-0.18899999999999997" upper="1.644" velocity="7"/>
    <parent link="link_13"/>
    <child link="link_14"/>
    <origin rpy="0 -0.017453292519943295 0" xyz="0 0 0.019700000000000002"/>
  </joint>
  <link name="link_15">
    <visual>
      <geometry>
        <mesh filename="package://xela_models/mesh/allegro/thumb_2.0.stl"/>
      </geometry>
      <material name="black"/>
    </visual>
    <collision>
      <geometry>
        <box size="0.0196 0.0275 0.042300000000000004"/>
      </geometry>
      <origin rpy="0 0 0" xyz="0 0 0.021150000000000002"/>
    </collision>
    <inertial>
      <mass value="0.0753"/>
      <origin rpy="0 0 0" xyz="0 0 0"/>
      <inertia ixx="2.90e-05" ixy="0.0" ixz="0.0" iyy="2.90e-05" iyz="0.0" izz="6.88e-06"/>
    </inertial>
  </link>
  <joint name="link_15_4x4_fixed" type="fixed">
    <origin rpy="0.0 1.5707963267948966 0.0" xyz="0.011 -0.012 0.021"/>
    <parent link="link_15"/>
    <child link="link_15_4x4_palm_link"/>
  </joint>
  <link name="link_15_4x4_palm_link">
    <collision>
      <origin rpy="0 0 0" xyz="0 0 0"/>
      <geometry>
        <mesh filename="package://xela_models/mesh/4x4.stl"/>
      </geometry>
    </collision>
    <visual>
      <origin rpy="0 0 0" xyz="0 0 0"/>
      <geometry>
        <mesh filename="package://xela_models/mesh/4x4.stl"/>
      </geometry>
      <material name="blue"/>
    </visual>
  </link>
  <joint name="joint_15" type="revolute">
    <axis xyz="0 1 0"/>
    <limit effort="15" lower="-0.162" upper="1.7189999999999999" velocity="7"/>
    <parent link="link_14"/>
    <child link="link_15"/>
    <origin xyz="0 0 0.0514"/>
    <!--allegro link size difference-0.004-->
  </joint>
  <joint name="3aftc_fixed" type="fixed">
    <origin rpy="1.5707963267948966 0.0 1.5707963267948966" xyz="-0.013 0.0 0.0315"/>
    <parent link="link_15"/>
    <child link="3aftc_palm_link"/>
  </joint>
  <link name="3aftc_palm_link">
    <collision>
      <origin rpy="0 0 0" xyz="0 0 0"/>
      <geometry>
        <mesh filename="package://xela_models/mesh/ft_c.stl"/>
      </geometry>
    </collision>
    <visual>
      <origin rpy="0 0 0" xyz="0 0 0"/>
      <geometry>
        <mesh filename="package://xela_models/mesh/ft_c.stl"/>
      </geometry>
      <material name="orange"/>
    </visual>
  </link>
  <!-- Enable the following 2 if you would like to see different options the same time -->
  <!-- <xacro:allegro_hand_right sequence="2" parent="world" x="0.2" tips="curved" /> -->
  <!-- <xacro:allegro_hand_right sequence="3" parent="world" x="-0.2" covers="0" palm="0" phalanges="0" tips="default"/> -->
</robot>
